âœ… All database indexes created successfully
Bot is running...
 * Serving Flask app 'main'
 * Debug mode: off
INFO:werkzeug:[31m[1mWARNING: This is a development server. Do not use it in a production deployment. Use a production WSGI server instead.[0m
 * Running on all addresses (0.0.0.0)
 * Running on http://127.0.0.1:8080
 * Running on http://172.30.0.2:8080
INFO:werkzeug:[33mPress CTRL+C to quit[0m
INFO:telethon.network.mtprotosender:Connecting to 149.154.167.51:443/TcpFull...
INFO:telethon.network.mtprotosender:Connection to 149.154.167.51:443/TcpFull complete!
INFO:telethon.client.users:Phone migrated to 4
INFO:telethon.client.telegrambaseclient:Reconnecting to new data center 4
INFO:telethon.network.mtprotosender:Disconnecting from 149.154.167.51:443/TcpFull...
INFO:telethon.network.mtprotosender:Disconnection from 149.154.167.51:443/TcpFull complete!
INFO:telethon.network.mtprotosender:Connecting to 149.154.167.91:443/TcpFull...
INFO:telethon.network.mtprotosender:Connection to 149.154.167.91:443/TcpFull complete!
INFO:telethon.network.mtprotosender:Disconnecting from 149.154.167.91:443/TcpFull...
INFO:telethon.network.mtprotosender:Disconnection from 149.154.167.91:443/TcpFull complete!
2025-07-14 15:41:53,176 (__init__.py:1115 MainThread) ERROR - TeleBot: "Infinity polling exception: ('Connection aborted.', ConnectionResetError(104, 'Connection reset by peer'))"
ERROR:TeleBot:Infinity polling exception: ('Connection aborted.', ConnectionResetError(104, 'Connection reset by peer'))
2025-07-14 15:41:53,180 (__init__.py:1117 MainThread) ERROR - TeleBot: "Exception traceback:
Traceback (most recent call last):
  File "/home/ubuntu/.local/lib/python3.13/site-packages/urllib3/connectionpool.py", line 787, in urlopen
    response = self._make_request(
        conn,
    ...<10 lines>...
        **response_kw,
    )
  File "/home/ubuntu/.local/lib/python3.13/site-packages/urllib3/connectionpool.py", line 534, in _make_request
    response = conn.getresponse()
  File "/home/ubuntu/.local/lib/python3.13/site-packages/urllib3/connection.py", line 565, in getresponse
    httplib_response = super().getresponse()
  File "/usr/lib/python3.13/http/client.py", line 1430, in getresponse
    response.begin()
    ~~~~~~~~~~~~~~^^
  File "/usr/lib/python3.13/http/client.py", line 331, in begin
    version, status, reason = self._read_status()
                              ~~~~~~~~~~~~~~~~~^^
  File "/usr/lib/python3.13/http/client.py", line 292, in _read_status
    line = str(self.fp.readline(_MAXLINE + 1), "iso-8859-1")
               ~~~~~~~~~~~~~~~~^^^^^^^^^^^^^^
  File "/usr/lib/python3.13/socket.py", line 719, in readinto
    return self._sock.recv_into(b)
           ~~~~~~~~~~~~~~~~~~~~^^^
  File "/usr/lib/python3.13/ssl.py", line 1304, in recv_into
    return self.read(nbytes, buffer)
           ~~~~~~~~~^^^^^^^^^^^^^^^^
  File "/usr/lib/python3.13/ssl.py", line 1138, in read
    return self._sslobj.read(len, buffer)
           ~~~~~~~~~~~~~~~~~^^^^^^^^^^^^^
ConnectionResetError: [Errno 104] Connection reset by peer

During handling of the above exception, another exception occurred:

Traceback (most recent call last):
  File "/home/ubuntu/.local/lib/python3.13/site-packages/requests/adapters.py", line 667, in send
    resp = conn.urlopen(
        method=request.method,
    ...<9 lines>...
        chunked=chunked,
    )
  File "/home/ubuntu/.local/lib/python3.13/site-packages/urllib3/connectionpool.py", line 841, in urlopen
    retries = retries.increment(
        method, url, error=new_e, _pool=self, _stacktrace=sys.exc_info()[2]
    )
  File "/home/ubuntu/.local/lib/python3.13/site-packages/urllib3/util/retry.py", line 474, in increment
    raise reraise(type(error), error, _stacktrace)
          ~~~~~~~^^^^^^^^^^^^^^^^^^^^^^^^^^^^^^^^^
  File "/home/ubuntu/.local/lib/python3.13/site-packages/urllib3/util/util.py", line 38, in reraise
    raise value.with_traceback(tb)
  File "/home/ubuntu/.local/lib/python3.13/site-packages/urllib3/connectionpool.py", line 787, in urlopen
    response = self._make_request(
        conn,
    ...<10 lines>...
        **response_kw,
    )
  File "/home/ubuntu/.local/lib/python3.13/site-packages/urllib3/connectionpool.py", line 534, in _make_request
    response = conn.getresponse()
  File "/home/ubuntu/.local/lib/python3.13/site-packages/urllib3/connection.py", line 565, in getresponse
    httplib_response = super().getresponse()
  File "/usr/lib/python3.13/http/client.py", line 1430, in getresponse
    response.begin()
    ~~~~~~~~~~~~~~^^
  File "/usr/lib/python3.13/http/client.py", line 331, in begin
    version, status, reason = self._read_status()
                              ~~~~~~~~~~~~~~~~~^^
  File "/usr/lib/python3.13/http/client.py", line 292, in _read_status
    line = str(self.fp.readline(_MAXLINE + 1), "iso-8859-1")
               ~~~~~~~~~~~~~~~~^^^^^^^^^^^^^^
  File "/usr/lib/python3.13/socket.py", line 719, in readinto
    return self._sock.recv_into(b)
           ~~~~~~~~~~~~~~~~~~~~^^^
  File "/usr/lib/python3.13/ssl.py", line 1304, in recv_into
    return self.read(nbytes, buffer)
           ~~~~~~~~~^^^^^^^^^^^^^^^^
  File "/usr/lib/python3.13/ssl.py", line 1138, in read
    return self._sslobj.read(len, buffer)
           ~~~~~~~~~~~~~~~~~^^^^^^^^^^^^^
urllib3.exceptions.ProtocolError: ('Connection aborted.', ConnectionResetError(104, 'Connection reset by peer'))

During handling of the above exception, another exception occurred:

Traceback (most recent call last):
  File "/home/ubuntu/.local/lib/python3.13/site-packages/telebot/__init__.py", line 1110, in infinity_polling
    self.polling(non_stop=True, timeout=timeout, long_polling_timeout=long_polling_timeout,
    ~~~~~~~~~~~~^^^^^^^^^^^^^^^^^^^^^^^^^^^^^^^^^^^^^^^^^^^^^^^^^^^^^^^^^^^^^^^^^^^^^^^^^^^
                 logger_level=logger_level, allowed_updates=allowed_updates, restart_on_change=False,
                 ^^^^^^^^^^^^^^^^^^^^^^^^^^^^^^^^^^^^^^^^^^^^^^^^^^^^^^^^^^^^^^^^^^^^^^^^^^^^^^^^^^^^
                 *args, **kwargs)
                 ^^^^^^^^^^^^^^^^
  File "/home/ubuntu/.local/lib/python3.13/site-packages/telebot/__init__.py", line 1198, in polling
    self.__threaded_polling(non_stop=non_stop, interval=interval, timeout=timeout, long_polling_timeout=long_polling_timeout,
    ~~~~~~~~~~~~~~~~~~~~~~~^^^^^^^^^^^^^^^^^^^^^^^^^^^^^^^^^^^^^^^^^^^^^^^^^^^^^^^^^^^^^^^^^^^^^^^^^^^^^^^^^^^^^^^^^^^^^^^^^^
                            logger_level=logger_level, allowed_updates=allowed_updates)
                            ^^^^^^^^^^^^^^^^^^^^^^^^^^^^^^^^^^^^^^^^^^^^^^^^^^^^^^^^^^^
  File "/home/ubuntu/.local/lib/python3.13/site-packages/telebot/__init__.py", line 1273, in __threaded_polling
    raise e
  File "/home/ubuntu/.local/lib/python3.13/site-packages/telebot/__init__.py", line 1235, in __threaded_polling
    self.worker_pool.raise_exceptions()
    ~~~~~~~~~~~~~~~~~~~~~~~~~~~~~~~~~^^
  File "/home/ubuntu/.local/lib/python3.13/site-packages/telebot/util.py", line 150, in raise_exceptions
    raise self.exception_info
  File "/home/ubuntu/.local/lib/python3.13/site-packages/telebot/util.py", line 93, in run
    task(*args, **kwargs)
    ~~~~^^^^^^^^^^^^^^^^^
  File "/home/ubuntu/.local/lib/python3.13/site-packages/telebot/__init__.py", line 9759, in _run_middlewares_and_handler
    result = handler['function'](message)
  File "/workspace/start.py", line 69, in handle_language_command
    bot.send_message(
    ~~~~~~~~~~~~~~~~^
        message.chat.id,
        ^^^^^^^^^^^^^^^^
        "Please select your language:\nÙŠØ±Ø¬Ù‰ Ø§Ø®ØªÙŠØ§Ø± Ù„ØºØªÙƒ:\nè¯·é€‰æ‹©ä½ çš„è¯­è¨€:",
        ^^^^^^^^^^^^^^^^^^^^^^^^^^^^^^^^^^^^^^^^^^^^^^^^^^^^^^^^^^^^^^^^^^^
        reply_markup=markup
        ^^^^^^^^^^^^^^^^^^^
    )
    ^
  File "/home/ubuntu/.local/lib/python3.13/site-packages/telebot/__init__.py", line 1800, in send_message
    apihelper.send_message(
    ~~~~~~~~~~~~~~~~~~~~~~^
        self.token, chat_id, text,
        ^^^^^^^^^^^^^^^^^^^^^^^^^^
    ...<2 lines>...
        reply_parameters=reply_parameters, link_preview_options=link_preview_options, business_connection_id=business_connection_id,
        ^^^^^^^^^^^^^^^^^^^^^^^^^^^^^^^^^^^^^^^^^^^^^^^^^^^^^^^^^^^^^^^^^^^^^^^^^^^^^^^^^^^^^^^^^^^^^^^^^^^^^^^^^^^^^^^^^^^^^^^^^^^^
        message_effect_id=message_effect_id, allow_paid_broadcast=allow_paid_broadcast))
        ^^^^^^^^^^^^^^^^^^^^^^^^^^^^^^^^^^^^^^^^^^^^^^^^^^^^^^^^^^^^^^^^^^^^^^^^^^^^^^^
  File "/home/ubuntu/.local/lib/python3.13/site-packages/telebot/apihelper.py", line 275, in send_message
    return _make_request(token, method_url, params=payload, method='post')
  File "/home/ubuntu/.local/lib/python3.13/site-packages/telebot/apihelper.py", line 162, in _make_request
    result = _get_req_session().request(
        method, request_url, params=params, files=files,
        timeout=(connect_timeout, read_timeout), proxies=proxy)
  File "/home/ubuntu/.local/lib/python3.13/site-packages/requests/sessions.py", line 589, in request
    resp = self.send(prep, **send_kwargs)
  File "/home/ubuntu/.local/lib/python3.13/site-packages/requests/sessions.py", line 703, in send
    r = adapter.send(request, **kwargs)
  File "/home/ubuntu/.local/lib/python3.13/site-packages/requests/adapters.py", line 682, in send
    raise ConnectionError(err, request=request)
requests.exceptions.ConnectionError: ('Connection aborted.', ConnectionResetError(104, 'Connection reset by peer'))
"
ERROR:TeleBot:Exception traceback:
Traceback (most recent call last):
  File "/home/ubuntu/.local/lib/python3.13/site-packages/urllib3/connectionpool.py", line 787, in urlopen
    response = self._make_request(
        conn,
    ...<10 lines>...
        **response_kw,
    )
  File "/home/ubuntu/.local/lib/python3.13/site-packages/urllib3/connectionpool.py", line 534, in _make_request
    response = conn.getresponse()
  File "/home/ubuntu/.local/lib/python3.13/site-packages/urllib3/connection.py", line 565, in getresponse
    httplib_response = super().getresponse()
  File "/usr/lib/python3.13/http/client.py", line 1430, in getresponse
    response.begin()
    ~~~~~~~~~~~~~~^^
  File "/usr/lib/python3.13/http/client.py", line 331, in begin
    version, status, reason = self._read_status()
                              ~~~~~~~~~~~~~~~~~^^
  File "/usr/lib/python3.13/http/client.py", line 292, in _read_status
    line = str(self.fp.readline(_MAXLINE + 1), "iso-8859-1")
               ~~~~~~~~~~~~~~~~^^^^^^^^^^^^^^
  File "/usr/lib/python3.13/socket.py", line 719, in readinto
    return self._sock.recv_into(b)
           ~~~~~~~~~~~~~~~~~~~~^^^
  File "/usr/lib/python3.13/ssl.py", line 1304, in recv_into
    return self.read(nbytes, buffer)
           ~~~~~~~~~^^^^^^^^^^^^^^^^
  File "/usr/lib/python3.13/ssl.py", line 1138, in read
    return self._sslobj.read(len, buffer)
           ~~~~~~~~~~~~~~~~~^^^^^^^^^^^^^
ConnectionResetError: [Errno 104] Connection reset by peer

During handling of the above exception, another exception occurred:

Traceback (most recent call last):
  File "/home/ubuntu/.local/lib/python3.13/site-packages/requests/adapters.py", line 667, in send
    resp = conn.urlopen(
        method=request.method,
    ...<9 lines>...
        chunked=chunked,
    )
  File "/home/ubuntu/.local/lib/python3.13/site-packages/urllib3/connectionpool.py", line 841, in urlopen
    retries = retries.increment(
        method, url, error=new_e, _pool=self, _stacktrace=sys.exc_info()[2]
    )
  File "/home/ubuntu/.local/lib/python3.13/site-packages/urllib3/util/retry.py", line 474, in increment
    raise reraise(type(error), error, _stacktrace)
          ~~~~~~~^^^^^^^^^^^^^^^^^^^^^^^^^^^^^^^^^
  File "/home/ubuntu/.local/lib/python3.13/site-packages/urllib3/util/util.py", line 38, in reraise
    raise value.with_traceback(tb)
  File "/home/ubuntu/.local/lib/python3.13/site-packages/urllib3/connectionpool.py", line 787, in urlopen
    response = self._make_request(
        conn,
    ...<10 lines>...
        **response_kw,
    )
  File "/home/ubuntu/.local/lib/python3.13/site-packages/urllib3/connectionpool.py", line 534, in _make_request
    response = conn.getresponse()
  File "/home/ubuntu/.local/lib/python3.13/site-packages/urllib3/connection.py", line 565, in getresponse
    httplib_response = super().getresponse()
  File "/usr/lib/python3.13/http/client.py", line 1430, in getresponse
    response.begin()
    ~~~~~~~~~~~~~~^^
  File "/usr/lib/python3.13/http/client.py", line 331, in begin
    version, status, reason = self._read_status()
                              ~~~~~~~~~~~~~~~~~^^
  File "/usr/lib/python3.13/http/client.py", line 292, in _read_status
    line = str(self.fp.readline(_MAXLINE + 1), "iso-8859-1")
               ~~~~~~~~~~~~~~~~^^^^^^^^^^^^^^
  File "/usr/lib/python3.13/socket.py", line 719, in readinto
    return self._sock.recv_into(b)
           ~~~~~~~~~~~~~~~~~~~~^^^
  File "/usr/lib/python3.13/ssl.py", line 1304, in recv_into
    return self.read(nbytes, buffer)
           ~~~~~~~~~^^^^^^^^^^^^^^^^
  File "/usr/lib/python3.13/ssl.py", line 1138, in read
    return self._sslobj.read(len, buffer)
           ~~~~~~~~~~~~~~~~~^^^^^^^^^^^^^
urllib3.exceptions.ProtocolError: ('Connection aborted.', ConnectionResetError(104, 'Connection reset by peer'))

During handling of the above exception, another exception occurred:

Traceback (most recent call last):
  File "/home/ubuntu/.local/lib/python3.13/site-packages/telebot/__init__.py", line 1110, in infinity_polling
    self.polling(non_stop=True, timeout=timeout, long_polling_timeout=long_polling_timeout,
    ~~~~~~~~~~~~^^^^^^^^^^^^^^^^^^^^^^^^^^^^^^^^^^^^^^^^^^^^^^^^^^^^^^^^^^^^^^^^^^^^^^^^^^^
                 logger_level=logger_level, allowed_updates=allowed_updates, restart_on_change=False,
                 ^^^^^^^^^^^^^^^^^^^^^^^^^^^^^^^^^^^^^^^^^^^^^^^^^^^^^^^^^^^^^^^^^^^^^^^^^^^^^^^^^^^^
                 *args, **kwargs)
                 ^^^^^^^^^^^^^^^^
  File "/home/ubuntu/.local/lib/python3.13/site-packages/telebot/__init__.py", line 1198, in polling
    self.__threaded_polling(non_stop=non_stop, interval=interval, timeout=timeout, long_polling_timeout=long_polling_timeout,
    ~~~~~~~~~~~~~~~~~~~~~~~^^^^^^^^^^^^^^^^^^^^^^^^^^^^^^^^^^^^^^^^^^^^^^^^^^^^^^^^^^^^^^^^^^^^^^^^^^^^^^^^^^^^^^^^^^^^^^^^^^
                            logger_level=logger_level, allowed_updates=allowed_updates)
                            ^^^^^^^^^^^^^^^^^^^^^^^^^^^^^^^^^^^^^^^^^^^^^^^^^^^^^^^^^^^
  File "/home/ubuntu/.local/lib/python3.13/site-packages/telebot/__init__.py", line 1273, in __threaded_polling
    raise e
  File "/home/ubuntu/.local/lib/python3.13/site-packages/telebot/__init__.py", line 1235, in __threaded_polling
    self.worker_pool.raise_exceptions()
    ~~~~~~~~~~~~~~~~~~~~~~~~~~~~~~~~~^^
  File "/home/ubuntu/.local/lib/python3.13/site-packages/telebot/util.py", line 150, in raise_exceptions
    raise self.exception_info
  File "/home/ubuntu/.local/lib/python3.13/site-packages/telebot/util.py", line 93, in run
    task(*args, **kwargs)
    ~~~~^^^^^^^^^^^^^^^^^
  File "/home/ubuntu/.local/lib/python3.13/site-packages/telebot/__init__.py", line 9759, in _run_middlewares_and_handler
    result = handler['function'](message)
  File "/workspace/start.py", line 69, in handle_language_command
    bot.send_message(
    ~~~~~~~~~~~~~~~~^
        message.chat.id,
        ^^^^^^^^^^^^^^^^
        "Please select your language:\nÙŠØ±Ø¬Ù‰ Ø§Ø®ØªÙŠØ§Ø± Ù„ØºØªÙƒ:\nè¯·é€‰æ‹©ä½ çš„è¯­è¨€:",
        ^^^^^^^^^^^^^^^^^^^^^^^^^^^^^^^^^^^^^^^^^^^^^^^^^^^^^^^^^^^^^^^^^^^
        reply_markup=markup
        ^^^^^^^^^^^^^^^^^^^
    )
    ^
  File "/home/ubuntu/.local/lib/python3.13/site-packages/telebot/__init__.py", line 1800, in send_message
    apihelper.send_message(
    ~~~~~~~~~~~~~~~~~~~~~~^
        self.token, chat_id, text,
        ^^^^^^^^^^^^^^^^^^^^^^^^^^
    ...<2 lines>...
        reply_parameters=reply_parameters, link_preview_options=link_preview_options, business_connection_id=business_connection_id,
        ^^^^^^^^^^^^^^^^^^^^^^^^^^^^^^^^^^^^^^^^^^^^^^^^^^^^^^^^^^^^^^^^^^^^^^^^^^^^^^^^^^^^^^^^^^^^^^^^^^^^^^^^^^^^^^^^^^^^^^^^^^^^
        message_effect_id=message_effect_id, allow_paid_broadcast=allow_paid_broadcast))
        ^^^^^^^^^^^^^^^^^^^^^^^^^^^^^^^^^^^^^^^^^^^^^^^^^^^^^^^^^^^^^^^^^^^^^^^^^^^^^^^
  File "/home/ubuntu/.local/lib/python3.13/site-packages/telebot/apihelper.py", line 275, in send_message
    return _make_request(token, method_url, params=payload, method='post')
  File "/home/ubuntu/.local/lib/python3.13/site-packages/telebot/apihelper.py", line 162, in _make_request
    result = _get_req_session().request(
        method, request_url, params=params, files=files,
        timeout=(connect_timeout, read_timeout), proxies=proxy)
  File "/home/ubuntu/.local/lib/python3.13/site-packages/requests/sessions.py", line 589, in request
    resp = self.send(prep, **send_kwargs)
  File "/home/ubuntu/.local/lib/python3.13/site-packages/requests/sessions.py", line 703, in send
    r = adapter.send(request, **kwargs)
  File "/home/ubuntu/.local/lib/python3.13/site-packages/requests/adapters.py", line 682, in send
    raise ConnectionError(err, request=request)
requests.exceptions.ConnectionError: ('Connection aborted.', ConnectionResetError(104, 'Connection reset by peer'))

INFO:telethon.network.mtprotosender:Connecting to 149.154.167.51:443/TcpFull...
INFO:telethon.network.mtprotosender:Connection to 149.154.167.51:443/TcpFull complete!
INFO:telethon.client.users:Phone migrated to 4
INFO:telethon.client.telegrambaseclient:Reconnecting to new data center 4
INFO:telethon.network.mtprotosender:Disconnecting from 149.154.167.51:443/TcpFull...
INFO:telethon.network.mtprotosender:Disconnection from 149.154.167.51:443/TcpFull complete!
INFO:telethon.network.mtprotosender:Connecting to 149.154.167.91:443/TcpFull...
INFO:telethon.network.mtprotosender:Connection to 149.154.167.91:443/TcpFull complete!
INFO:telethon.network.mtprotosender:Disconnecting from 149.154.167.91:443/TcpFull...
INFO:telethon.network.mtprotosender:Disconnection from 149.154.167.91:443/TcpFull complete!
âœ… All database indexes created successfully
Bot is running...
 * Serving Flask app 'main'
 * Debug mode: off
INFO:werkzeug:[31m[1mWARNING: This is a development server. Do not use it in a production deployment. Use a production WSGI server instead.[0m
 * Running on all addresses (0.0.0.0)
 * Running on http://127.0.0.1:8080
 * Running on http://172.30.0.2:8080
INFO:werkzeug:[33mPress CTRL+C to quit[0m
INFO:telethon.network.mtprotosender:Connecting to 149.154.167.51:443/TcpFull...
INFO:telethon.network.mtprotosender:Connection to 149.154.167.51:443/TcpFull complete!
INFO:telethon.client.users:Phone migrated to 4
INFO:telethon.client.telegrambaseclient:Reconnecting to new data center 4
INFO:telethon.network.mtprotosender:Disconnecting from 149.154.167.51:443/TcpFull...
INFO:telethon.network.mtprotosender:Disconnection from 149.154.167.51:443/TcpFull complete!
INFO:telethon.network.mtprotosender:Connecting to 149.154.167.92:443/TcpFull...
INFO:telethon.network.mtprotosender:Connection to 149.154.167.92:443/TcpFull complete!
INFO:telethon.network.mtprotosender:Disconnecting from 149.154.167.92:443/TcpFull...
INFO:telethon.network.mtprotosender:Disconnection from 149.154.167.92:443/TcpFull complete!
âœ… All database indexes created successfully
Traceback (most recent call last):
  File "/workspace/main.py", line 11, in <module>
    import cancel
  File "/workspace/cancel.py", line 9, in <module>
    from translations import TRANSLATIONS
ModuleNotFoundError: No module named 'translations'
âœ… All database indexes created successfully
Bot is running...
 * Serving Flask app 'main'
 * Debug mode: off
INFO:werkzeug:[31m[1mWARNING: This is a development server. Do not use it in a production deployment. Use a production WSGI server instead.[0m
 * Running on all addresses (0.0.0.0)
 * Running on http://127.0.0.1:8080
 * Running on http://172.30.0.2:8080
INFO:werkzeug:[33mPress CTRL+C to quit[0m
